
Error Timestamp: 2024-01-28 15:08:08
Error Dump:
[Errno 2] No such file or directory: 'kdsjn,d'
Traceback (most recent call last):
  File "c:\Users\disha\OneDrive\Documents\Design and simulation of Operating Systems\Milestone1\MainClass.py", line 18, in load_program
    b_size, PC, loader_address = loader.loader(verbose)
                                 ^^^^^^^^^^^^^^^^^^^^^^
  File "c:\Users\disha\OneDrive\Documents\Design and simulation of Operating Systems\Milestone1\loader.py", line 10, in loader
    with open(self.file_path, 'rb') as file:
         ^^^^^^^^^^^^^^^^^^^^^^^^^^
FileNotFoundError: [Errno 2] No such file or directory: 'kdsjn,d'

Error Timestamp: 2024-01-28 17:26:58
Error Dump:
Loader.loader() takes 1 positional argument but 2 were given
Traceback (most recent call last):
  File "c:\Users\disha\OneDrive\Documents\Design and simulation of Operating Systems\Milestone1\MainClass.py", line 18, in load_program
    b_size, PC, loader_address = loader.loader(verbose)
                                 ^^^^^^^^^^^^^^^^^^^^^^
TypeError: Loader.loader() takes 1 positional argument but 2 were given

Error Timestamp: 2024-01-28 17:28:14
Error Dump:
Loader.loader() takes 1 positional argument but 2 were given
Traceback (most recent call last):
  File "c:\Users\disha\OneDrive\Documents\Design and simulation of Operating Systems\Milestone1\MainClass.py", line 18, in load_program
    b_size, PC, loader_address = loader.loader(verbose)
                                 ^^^^^^^^^^^^^^^^^^^^^^
TypeError: Loader.loader() takes 1 positional argument but 2 were given

Error Timestamp: 2024-01-28 19:05:21
Error Dump:
Error: Cannot load a new program while another program is already ready to run at the same location.
Traceback (most recent call last):
  File "c:\Users\disha\OneDrive\Documents\Design and simulation of Operating Systems\Milestone1\MainClass.py", line 114, in start
    self.run_command(command, args)
  File "c:\Users\disha\OneDrive\Documents\Design and simulation of Operating Systems\Milestone1\MainClass.py", line 77, in run_command
    self.load_program(filename, verbose)
  File "c:\Users\disha\OneDrive\Documents\Design and simulation of Operating Systems\Milestone1\MainClass.py", line 20, in load_program
    raise ProgramLoadError()
ProgramLoadError: Error: Cannot load a new program while another program is already ready to run at the same location.

Error Timestamp: 2024-02-07 15:35:29
Error Dump:
[Errno 2] No such file or directory: 'int.osx'
Traceback (most recent call last):
  File "C:\Users\disha\OneDrive\Documents\Design and simulation of Operating Systems\Milestone1\MainClass.py", line 23, in load_program
    b_size, PC, loader_address = loader.loader(verbose)
                                 ^^^^^^^^^^^^^^^^^^^^^^
  File "C:\Users\disha\OneDrive\Documents\Design and simulation of Operating Systems\Milestone1\loader.py", line 10, in loader
    with open(self.file_path, 'rb') as file:
         ^^^^^^^^^^^^^^^^^^^^^^^^^^
FileNotFoundError: [Errno 2] No such file or directory: 'int.osx'

Error Timestamp: 2024-02-07 15:49:02
Error Dump:
Error: Cannot load a new program while another program is already ready to run at the same location.
Traceback (most recent call last):
  File "C:\Users\disha\OneDrive\Documents\Design and simulation of Operating Systems\Milestone1\MainClass.py", line 114, in start
    self.run_command(command, args)
  File "C:\Users\disha\OneDrive\Documents\Design and simulation of Operating Systems\Milestone1\MainClass.py", line 77, in run_command
    self.load_program(filename, verbose)
  File "C:\Users\disha\OneDrive\Documents\Design and simulation of Operating Systems\Milestone1\MainClass.py", line 20, in load_program
    raise ProgramLoadError()
ProgramLoadError: Error: Cannot load a new program while another program is already ready to run at the same location.

Error Timestamp: 2024-02-09 10:02:55
Error Dump:
'Queue' object has no attribute 'append'
Traceback (most recent call last):
  File "C:\Users\disha\OneDrive\Documents\Design and simulation of Operating Systems\Milestone1\MainClass.py", line 22, in load_program
    self.cpus.append(CPU(self.memory, self.registers, loader_address, b_size, PC, verbose))
    ^^^^^^^^^^^^^^^^
AttributeError: 'Queue' object has no attribute 'append'

Error Timestamp: 2024-02-09 10:04:26
Error Dump:
'Queue' object has no attribute 'append'
Traceback (most recent call last):
  File "C:\Users\disha\OneDrive\Documents\Design and simulation of Operating Systems\Milestone1\MainClass.py", line 22, in load_program
    self.cpus.put(CPU(self.memory, self.registers, loader_address, b_size, PC, verbose))
    ^^^^^^^^^^^^^^^^
AttributeError: 'Queue' object has no attribute 'append'

Error Timestamp: 2024-02-09 10:15:35
Error Dump:
[WinError 216] This version of %1 is not compatible with the version of Windows you're running. Check your computer's system information and then contact the software publisher
Traceback (most recent call last):
  File "C:\Users\disha\OneDrive\Documents\Design and simulation of Operating Systems\Milestone1\MainClass.py", line 129, in start
    self.run_command(command, args)
  File "C:\Users\disha\OneDrive\Documents\Design and simulation of Operating Systems\Milestone1\MainClass.py", line 103, in run_command
    self.osx(filename, verbose)
  File "C:\Users\disha\OneDrive\Documents\Design and simulation of Operating Systems\Milestone1\MainClass.py", line 114, in osx
    subprocess.run(command, check=True)
  File "C:\Users\disha\anaconda3\Lib\subprocess.py", line 548, in run
    with Popen(*popenargs, **kwargs) as process:
         ^^^^^^^^^^^^^^^^^^^^^^^^^^^
  File "C:\Users\disha\anaconda3\Lib\subprocess.py", line 1026, in __init__
    self._execute_child(args, executable, preexec_fn, close_fds,
  File "C:\Users\disha\anaconda3\Lib\subprocess.py", line 1538, in _execute_child
    hp, ht, pid, tid = _winapi.CreateProcess(executable, args,
                       ^^^^^^^^^^^^^^^^^^^^^^^^^^^^^^^^^^^^^^^
OSError: [WinError 216] This version of %1 is not compatible with the version of Windows you're running. Check your computer's system information and then contact the software publisher

Error Timestamp: 2024-02-09 10:18:53
Error Dump:
[WinError 216] This version of %1 is not compatible with the version of Windows you're running. Check your computer's system information and then contact the software publisher
Traceback (most recent call last):
  File "C:\Users\disha\OneDrive\Documents\Design and simulation of Operating Systems\Milestone1\MainClass.py", line 131, in start
    self.run_command(command, args)
  File "C:\Users\disha\OneDrive\Documents\Design and simulation of Operating Systems\Milestone1\MainClass.py", line 103, in run_command
    self.osx(filename, verbose)
  File "C:\Users\disha\OneDrive\Documents\Design and simulation of Operating Systems\Milestone1\MainClass.py", line 114, in osx
    subprocess.run(command, check=True)
  File "C:\Users\disha\anaconda3\Lib\subprocess.py", line 548, in run
    with Popen(*popenargs, **kwargs) as process:
         ^^^^^^^^^^^^^^^^^^^^^^^^^^^
  File "C:\Users\disha\anaconda3\Lib\subprocess.py", line 1026, in __init__
    self._execute_child(args, executable, preexec_fn, close_fds,
  File "C:\Users\disha\anaconda3\Lib\subprocess.py", line 1538, in _execute_child
    hp, ht, pid, tid = _winapi.CreateProcess(executable, args,
                       ^^^^^^^^^^^^^^^^^^^^^^^^^^^^^^^^^^^^^^^
OSError: [WinError 216] This version of %1 is not compatible with the version of Windows you're running. Check your computer's system information and then contact the software publisher

Error Timestamp: 2024-02-09 10:22:51
Error Dump:
VMShell.run_program() missing 1 required positional argument: 'verbose'
Traceback (most recent call last):
  File "C:\Users\disha\OneDrive\Documents\Design and simulation of Operating Systems\Milestone1\MainClass.py", line 130, in start
    args = parts[1:]
  File "C:\Users\disha\OneDrive\Documents\Design and simulation of Operating Systems\Milestone1\MainClass.py", line 82, in run_command
    elif command == "run":
        ^^^^^^^^^^^^^^^^^^^
TypeError: VMShell.run_program() missing 1 required positional argument: 'verbose'

Error Timestamp: 2024-02-13 13:57:55
Error Dump:
'Loader' object has no attribute 'stack'
Traceback (most recent call last):
  File "C:\Users\brade\Documents\A School Work\OS\Group OS\Design-and-simulation-of-Operating-Systems\Design-and-simulation-of-Operating-Systems\Milestone1\MainClass.py", line 136, in start
    self.run_command(command, args)
  File "C:\Users\brade\Documents\A School Work\OS\Group OS\Design-and-simulation-of-Operating-Systems\Design-and-simulation-of-Operating-Systems\Milestone1\MainClass.py", line 109, in run_command
    self.osx(filename, verbose)
  File "C:\Users\brade\Documents\A School Work\OS\Group OS\Design-and-simulation-of-Operating-Systems\Design-and-simulation-of-Operating-Systems\Milestone1\MainClass.py", line 116, in osx
    load_address = self.loader.stack[-1] + 1
                   ^^^^^^^^^^^^^^^^^
AttributeError: 'Loader' object has no attribute 'stack'

Error Timestamp: 2024-02-13 13:59:38
Error Dump:
'Loader' object has no attribute 'stack'
Traceback (most recent call last):
  File "C:\Users\brade\Documents\A School Work\OS\Group OS\Design-and-simulation-of-Operating-Systems\Design-and-simulation-of-Operating-Systems\Milestone1\MainClass.py", line 136, in start
    self.run_command(command, args)
  File "C:\Users\brade\Documents\A School Work\OS\Group OS\Design-and-simulation-of-Operating-Systems\Design-and-simulation-of-Operating-Systems\Milestone1\MainClass.py", line 109, in run_command
    self.osx(filename, verbose)
  File "C:\Users\brade\Documents\A School Work\OS\Group OS\Design-and-simulation-of-Operating-Systems\Design-and-simulation-of-Operating-Systems\Milestone1\MainClass.py", line 116, in osx
    load_address = self.loader.stack[-1] + 1
                   ^^^^^^^^^^^^^^^^^
AttributeError: 'Loader' object has no attribute 'stack'

Error Timestamp: 2024-02-13 13:59:54
Error Dump:
[WinError 216] This version of %1 is not compatible with the version of Windows you're running. Check your computer's system information and then contact the software publisher
Traceback (most recent call last):
  File "C:\Users\brade\Documents\A School Work\OS\Group OS\Design-and-simulation-of-Operating-Systems\Design-and-simulation-of-Operating-Systems\Milestone1\MainClass.py", line 136, in start
    self.run_command(command, args)
  File "C:\Users\brade\Documents\A School Work\OS\Group OS\Design-and-simulation-of-Operating-Systems\Design-and-simulation-of-Operating-Systems\Milestone1\MainClass.py", line 109, in run_command
    self.osx(filename, verbose)
  File "C:\Users\brade\Documents\A School Work\OS\Group OS\Design-and-simulation-of-Operating-Systems\Design-and-simulation-of-Operating-Systems\Milestone1\MainClass.py", line 119, in osx
    subprocess.run(command, check=True)
  File "C:\Users\brade\anaconda3\Lib\subprocess.py", line 548, in run
    with Popen(*popenargs, **kwargs) as process:
         ^^^^^^^^^^^^^^^^^^^^^^^^^^^
  File "C:\Users\brade\anaconda3\Lib\subprocess.py", line 1026, in __init__
    self._execute_child(args, executable, preexec_fn, close_fds,
  File "C:\Users\brade\anaconda3\Lib\subprocess.py", line 1538, in _execute_child
    hp, ht, pid, tid = _winapi.CreateProcess(executable, args,
                       ^^^^^^^^^^^^^^^^^^^^^^^^^^^^^^^^^^^^^^^
OSError: [WinError 216] This version of %1 is not compatible with the version of Windows you're running. Check your computer's system information and then contact the software publisher

Error Timestamp: 2024-02-13 14:01:37
Error Dump:
Command 'osx.exe int.asm 6' returned non-zero exit status 1.
Traceback (most recent call last):
  File "C:\Users\brade\Documents\A School Work\OS\Group OS\Design-and-simulation-of-Operating-Systems\Design-and-simulation-of-Operating-Systems\Milestone1\MainClass.py", line 119, in osx
    subprocess.run(command, check=True, shell=True)  # Add shell=True parameter
    ^^^^^^^^^^^^^^^^^^^^^^^^^^^^^^^^^^^^^^^^^^^^^^^
  File "C:\Users\brade\anaconda3\Lib\subprocess.py", line 571, in run
    raise CalledProcessError(retcode, process.args,
subprocess.CalledProcessError: Command 'osx.exe int.asm 6' returned non-zero exit status 1.

Error Timestamp: 2024-02-13 14:05:33
Error Dump:
expected str, bytes or os.PathLike object, not int
Traceback (most recent call last):
  File "C:\Users\brade\Documents\A School Work\OS\Group OS\Design-and-simulation-of-Operating-Systems\Design-and-simulation-of-Operating-Systems\Milestone1\MainClass.py", line 137, in start
    self.run_command(command, args)
  File "C:\Users\brade\Documents\A School Work\OS\Group OS\Design-and-simulation-of-Operating-Systems\Design-and-simulation-of-Operating-Systems\Milestone1\MainClass.py", line 109, in run_command
    self.osx(filename, verbose)
  File "C:\Users\brade\Documents\A School Work\OS\Group OS\Design-and-simulation-of-Operating-Systems\Design-and-simulation-of-Operating-Systems\Milestone1\MainClass.py", line 120, in osx
    subprocess.run(brkt_command, check=False, shell=True)  # Add shell=True parameter
    ^^^^^^^^^^^^^^^^^^^^^^^^^^^^^^^^^^^^^^^^^^^^^^^^^^^^^
  File "C:\Users\brade\anaconda3\Lib\subprocess.py", line 548, in run
    with Popen(*popenargs, **kwargs) as process:
         ^^^^^^^^^^^^^^^^^^^^^^^^^^^
  File "C:\Users\brade\anaconda3\Lib\subprocess.py", line 1026, in __init__
    self._execute_child(args, executable, preexec_fn, close_fds,
  File "C:\Users\brade\anaconda3\Lib\subprocess.py", line 1462, in _execute_child
    args = list2cmdline(args)
           ^^^^^^^^^^^^^^^^^^
  File "C:\Users\brade\anaconda3\Lib\subprocess.py", line 608, in list2cmdline
    for arg in map(os.fsdecode, seq):
  File "<frozen os>", line 824, in fsdecode
TypeError: expected str, bytes or os.PathLike object, not int

Error Timestamp: 2024-02-14 15:42:04
Error Dump:
not writable
Traceback (most recent call last):
  File "C:\Users\disha\OneDrive\Documents\Design and simulation of Operating Systems\Milestone1\MainClass.py", line 23, in load_program
    b_size, PC, loader_address = self.loader.loader(filename, verbose)
                                 ^^^^^^^^^^^^^^^^^^^^^^^^^^^^^^^^^^^^^
  File "C:\Users\disha\OneDrive\Documents\Design and simulation of Operating Systems\Milestone1\loader.py", line 17, in loader
    self.print_errordump('ProgramLoadError')
  File "C:\Users\disha\OneDrive\Documents\Design and simulation of Operating Systems\Milestone1\loader.py", line 228, in print_errordump
    file.write(error)
io.UnsupportedOperation: not writable
