
Error Timestamp: 2024-03-21 15:31:36
Error Dump:
invalid literal for int() with base 10: ''
Traceback (most recent call last):
  File "C:\Users\disha\OneDrive\Documents\Design and simulation of Operating Systems\Milestone1\MainClass.py", line 412, in start
    self.run_command(command, args)
  File "C:\Users\disha\OneDrive\Documents\Design and simulation of Operating Systems\Milestone1\MainClass.py", line 331, in run_command
    self.mfq()
  File "C:\Users\disha\OneDrive\Documents\Design and simulation of Operating Systems\Milestone1\MainClass.py", line 128, in mfq
    self.alternate_roundrobin(quantums = 4, queue = self.ready)
  File "C:\Users\disha\OneDrive\Documents\Design and simulation of Operating Systems\Milestone1\MainClass.py", line 154, in alternate_roundrobin
    running.execute_single_instruction()
  File "C:\Users\disha\OneDrive\Documents\Design and simulation of Operating Systems\Milestone1\CPU.py", line 177, in execute_single_instruction
    self.execute(instruction)
  File "C:\Users\disha\OneDrive\Documents\Design and simulation of Operating Systems\Milestone1\CPU.py", line 70, in execute
    swi1.executeSWI(destination)
  File "C:\Users\disha\OneDrive\Documents\Design and simulation of Operating Systems\Milestone1\SWI.py", line 15, in executeSWI
    self.input_stuff()
  File "C:\Users\disha\OneDrive\Documents\Design and simulation of Operating Systems\Milestone1\SWI.py", line 26, in input_stuff
    self.registers.write('R2', int(value1))
                               ^^^^^^^^^^^
ValueError: invalid literal for int() with base 10: ''

Error Timestamp: 2024-03-21 18:01:30
Error Dump:
Error: Cannot load a new program while another program is already ready to run at the same location.
Traceback (most recent call last):
  File "C:\Users\disha\OneDrive\Documents\Design and simulation of Operating Systems\Milestone1\MainClass.py", line 35, in load_program
    b_size, first_instruction_address, loader_address = self.loader.loader(filename, self.verbose)
                                                        ^^^^^^^^^^^^^^^^^^^^^^^^^^^^^^^^^^^^^^^^^^
  File "C:\Users\disha\OneDrive\Documents\Design and simulation of Operating Systems\Milestone1\loader.py", line 19, in loader
    raise ProgramLoadError()
ProgramLoadError.ProgramLoadError: Error: Cannot load a new program while another program is already ready to run at the same location.

Error Timestamp: 2024-03-22 12:35:38
Error Dump:
list index out of range
Traceback (most recent call last):
  File "C:\Users\disha\OneDrive\Documents\Design and simulation of Operating Systems\Milestone1\MainClass.py", line 477, in start
    self.run_command(command, args)
  File "C:\Users\disha\OneDrive\Documents\Design and simulation of Operating Systems\Milestone1\MainClass.py", line 380, in run_command
    arrival_time = args[i + 1]
                   ~~~~^^^^^^^
IndexError: list index out of range

Error Timestamp: 2024-03-22 12:50:39
Error Dump:
invalid literal for int() with base 10: ''
Traceback (most recent call last):
  File "C:\Users\disha\OneDrive\Documents\Design and simulation of Operating Systems\Milestone1\MainClass.py", line 475, in start
    self.run_command(command, args)
  File "C:\Users\disha\OneDrive\Documents\Design and simulation of Operating Systems\Milestone1\MainClass.py", line 394, in run_command
    self.mfq()
  File "C:\Users\disha\OneDrive\Documents\Design and simulation of Operating Systems\Milestone1\MainClass.py", line 138, in mfq
    self.alternate_roundrobin(quantums = 4, queue = self.ready)
  File "C:\Users\disha\OneDrive\Documents\Design and simulation of Operating Systems\Milestone1\MainClass.py", line 165, in alternate_roundrobin
    running.execute_single_instruction()
  File "C:\Users\disha\OneDrive\Documents\Design and simulation of Operating Systems\Milestone1\CPU.py", line 181, in execute_single_instruction
    self.execute(instruction)
  File "C:\Users\disha\OneDrive\Documents\Design and simulation of Operating Systems\Milestone1\CPU.py", line 72, in execute
    swi1.executeSWI(destination)
  File "C:\Users\disha\OneDrive\Documents\Design and simulation of Operating Systems\Milestone1\SWI.py", line 15, in executeSWI
    self.input_stuff()
  File "C:\Users\disha\OneDrive\Documents\Design and simulation of Operating Systems\Milestone1\SWI.py", line 26, in input_stuff
    self.registers.write('R2', int(value1))
                               ^^^^^^^^^^^
ValueError: invalid literal for int() with base 10: ''

Error Timestamp: 2024-03-22 13:08:59
Error Dump:
invalid literal for int() with base 10: ''
Traceback (most recent call last):
  File "C:\Users\disha\OneDrive\Documents\Design and simulation of Operating Systems\MileStone1\MainClass.py", line 483, in start
    self.run_command(command, args)
  File "C:\Users\disha\OneDrive\Documents\Design and simulation of Operating Systems\MileStone1\MainClass.py", line 402, in run_command
    self.mfq()
  File "C:\Users\disha\OneDrive\Documents\Design and simulation of Operating Systems\MileStone1\MainClass.py", line 142, in mfq
    self.alternate_roundrobin(quantums = 4, queue = self.ready)
  File "C:\Users\disha\OneDrive\Documents\Design and simulation of Operating Systems\MileStone1\MainClass.py", line 172, in alternate_roundrobin
    running.execute_single_instruction()
  File "C:\Users\disha\OneDrive\Documents\Design and simulation of Operating Systems\MileStone1\CPU.py", line 182, in execute_single_instruction
    self.execute(instruction)
  File "C:\Users\disha\OneDrive\Documents\Design and simulation of Operating Systems\MileStone1\CPU.py", line 72, in execute
    swi1.executeSWI(destination)
  File "C:\Users\disha\OneDrive\Documents\Design and simulation of Operating Systems\MileStone1\SWI.py", line 15, in executeSWI
    self.input_stuff()
  File "C:\Users\disha\OneDrive\Documents\Design and simulation of Operating Systems\MileStone1\SWI.py", line 26, in input_stuff
    self.registers.write('R2', int(value1))
                               ^^^^^^^^^^^
ValueError: invalid literal for int() with base 10: ''

Error Timestamp: 2024-03-22 13:13:03
Error Dump:
invalid literal for int() with base 10: ''
Traceback (most recent call last):
  File "C:\Users\disha\OneDrive\Documents\Design and simulation of Operating Systems\MileStone1\MainClass.py", line 485, in start
    self.run_command(command, args)
  File "C:\Users\disha\OneDrive\Documents\Design and simulation of Operating Systems\MileStone1\MainClass.py", line 404, in run_command
    self.mfq()
  File "C:\Users\disha\OneDrive\Documents\Design and simulation of Operating Systems\MileStone1\MainClass.py", line 142, in mfq
    self.alternate_roundrobin(quantums = 4, queue = self.ready)
  File "C:\Users\disha\OneDrive\Documents\Design and simulation of Operating Systems\MileStone1\MainClass.py", line 172, in alternate_roundrobin
    running.execute_single_instruction()
  File "C:\Users\disha\OneDrive\Documents\Design and simulation of Operating Systems\MileStone1\CPU.py", line 182, in execute_single_instruction
    self.execute(instruction)
  File "C:\Users\disha\OneDrive\Documents\Design and simulation of Operating Systems\MileStone1\CPU.py", line 72, in execute
    swi1.executeSWI(destination)
  File "C:\Users\disha\OneDrive\Documents\Design and simulation of Operating Systems\MileStone1\SWI.py", line 15, in executeSWI
    self.input_stuff()
  File "C:\Users\disha\OneDrive\Documents\Design and simulation of Operating Systems\MileStone1\SWI.py", line 26, in input_stuff
    self.registers.write('R2', int(value1))
                               ^^^^^^^^^^^
ValueError: invalid literal for int() with base 10: ''

Error Timestamp: 2024-03-22 13:16:10
Error Dump:
invalid literal for int() with base 10: ''
Traceback (most recent call last):
  File "C:\Users\disha\OneDrive\Documents\Design and simulation of Operating Systems\MileStone1\MainClass.py", line 484, in start
    self.run_command(command, args)
  File "C:\Users\disha\OneDrive\Documents\Design and simulation of Operating Systems\MileStone1\MainClass.py", line 403, in run_command
    self.mfq()
  File "C:\Users\disha\OneDrive\Documents\Design and simulation of Operating Systems\MileStone1\MainClass.py", line 142, in mfq
    self.alternate_roundrobin(quantums = 4, queue = self.ready)
  File "C:\Users\disha\OneDrive\Documents\Design and simulation of Operating Systems\MileStone1\MainClass.py", line 171, in alternate_roundrobin
    running.execute_single_instruction()
  File "C:\Users\disha\OneDrive\Documents\Design and simulation of Operating Systems\MileStone1\CPU.py", line 182, in execute_single_instruction
    self.execute(instruction)
  File "C:\Users\disha\OneDrive\Documents\Design and simulation of Operating Systems\MileStone1\CPU.py", line 72, in execute
    swi1.executeSWI(destination)
  File "C:\Users\disha\OneDrive\Documents\Design and simulation of Operating Systems\MileStone1\SWI.py", line 15, in executeSWI
    self.input_stuff()
  File "C:\Users\disha\OneDrive\Documents\Design and simulation of Operating Systems\MileStone1\SWI.py", line 26, in input_stuff
    self.registers.write('R2', int(value1))
                               ^^^^^^^^^^^
ValueError: invalid literal for int() with base 10: ''

Error Timestamp: 2024-03-22 13:16:40
Error Dump:
invalid literal for int() with base 10: ''
Traceback (most recent call last):
  File "C:\Users\disha\OneDrive\Documents\Design and simulation of Operating Systems\MileStone1\MainClass.py", line 484, in start
    self.run_command(command, args)
  File "C:\Users\disha\OneDrive\Documents\Design and simulation of Operating Systems\MileStone1\MainClass.py", line 403, in run_command
    self.mfq()
  File "C:\Users\disha\OneDrive\Documents\Design and simulation of Operating Systems\MileStone1\MainClass.py", line 142, in mfq
    self.alternate_roundrobin(quantums = 4, queue = self.ready)
  File "C:\Users\disha\OneDrive\Documents\Design and simulation of Operating Systems\MileStone1\MainClass.py", line 171, in alternate_roundrobin
    running.execute_single_instruction()
  File "C:\Users\disha\OneDrive\Documents\Design and simulation of Operating Systems\MileStone1\CPU.py", line 182, in execute_single_instruction
    self.execute(instruction)
  File "C:\Users\disha\OneDrive\Documents\Design and simulation of Operating Systems\MileStone1\CPU.py", line 72, in execute
    swi1.executeSWI(destination)
  File "C:\Users\disha\OneDrive\Documents\Design and simulation of Operating Systems\MileStone1\SWI.py", line 15, in executeSWI
    self.input_stuff()
  File "C:\Users\disha\OneDrive\Documents\Design and simulation of Operating Systems\MileStone1\SWI.py", line 26, in input_stuff
    self.registers.write('R2', int(value1))
                               ^^^^^^^^^^^
ValueError: invalid literal for int() with base 10: ''

Error Timestamp: 2024-03-22 14:49:07
Error Dump:
list.remove(x): x not in list
Traceback (most recent call last):
  File "C:\Users\disha\OneDrive\Documents\Design and simulation of Operating Systems\MileStone1\MainClass.py", line 478, in start
    self.run_command(command, args)
  File "C:\Users\disha\OneDrive\Documents\Design and simulation of Operating Systems\MileStone1\MainClass.py", line 397, in run_command
    self.mfq()
  File "C:\Users\disha\OneDrive\Documents\Design and simulation of Operating Systems\MileStone1\MainClass.py", line 140, in mfq
    self.alternate_roundrobin(quantums = 1, queue = self.fcfs_queue)
  File "C:\Users\disha\OneDrive\Documents\Design and simulation of Operating Systems\MileStone1\MainClass.py", line 231, in alternate_roundrobin
    self.loader.remove_loader_address(running.loader_address,running.b_size)
  File "C:\Users\disha\OneDrive\Documents\Design and simulation of Operating Systems\MileStone1\loader.py", line 10, in remove_loader_address
    self.loader_address_stack.remove(loader_address+b_size)
ValueError: list.remove(x): x not in list

Error Timestamp: 2024-03-22 15:00:44
Error Dump:
Error: Cannot load a new program while another program is already ready to run at the same location.
Traceback (most recent call last):
  File "C:\Users\disha\OneDrive\Documents\Design and simulation of Operating Systems\MileStone1\MainClass.py", line 35, in load_program
    b_size, first_instruction_address, loader_address = self.loader.loader(filename, self.verbose)
                                                        ^^^^^^^^^^^^^^^^^^^^^^^^^^^^^^^^^^^^^^^^^^
  File "C:\Users\disha\OneDrive\Documents\Design and simulation of Operating Systems\MileStone1\loader.py", line 19, in loader
    raise ProgramLoadError()
ProgramLoadError.ProgramLoadError: Error: Cannot load a new program while another program is already ready to run at the same location.

Error Timestamp: 2024-03-22 15:02:40
Error Dump:
Error: Cannot load a new program while another program is already ready to run at the same location.
Traceback (most recent call last):
  File "C:\Users\disha\OneDrive\Documents\Design and simulation of Operating Systems\MileStone1\MainClass.py", line 35, in load_program
    b_size, first_instruction_address, loader_address = self.loader.loader(filename, self.verbose)
                                                        ^^^^^^^^^^^^^^^^^^^^^^^^^^^^^^^^^^^^^^^^^^
  File "C:\Users\disha\OneDrive\Documents\Design and simulation of Operating Systems\MileStone1\loader.py", line 19, in loader
    raise ProgramLoadError()
ProgramLoadError.ProgramLoadError: Error: Cannot load a new program while another program is already ready to run at the same location.

Error Timestamp: 2024-03-26 17:21:38
Error Dump:
Error: Cannot load a new program while another program is already ready to run at the same location.
Traceback (most recent call last):
  File "C:\Users\disha\OneDrive\Documents\Design and simulation of Operating Systems\MileStone1\MainClass.py", line 35, in load_program
    b_size, first_instruction_address, loader_address = self.loader.loader(filename, self.verbose)
                                                        ^^^^^^^^^^^^^^^^^^^^^^^^^^^^^^^^^^^^^^^^^^
  File "C:\Users\disha\OneDrive\Documents\Design and simulation of Operating Systems\MileStone1\loader.py", line 19, in loader
    raise ProgramLoadError()
ProgramLoadError.ProgramLoadError: Error: Cannot load a new program while another program is already ready to run at the same location.

Error Timestamp: 2024-03-28 14:40:00
Error Dump:
[Errno 2] No such file or directory: 'long.osx'
Traceback (most recent call last):
  File "C:\Users\disha\OneDrive\Documents\Design and simulation of Operating Systems\MileStone1\MainClass.py", line 35, in load_program
    b_size, first_instruction_address, loader_address = self.loader.loader(filename, self.verbose)
                                                        ^^^^^^^^^^^^^^^^^^^^^^^^^^^^^^^^^^^^^^^^^^
  File "C:\Users\disha\OneDrive\Documents\Design and simulation of Operating Systems\MileStone1\loader.py", line 14, in loader
    with open(file_path, 'rb') as file:
         ^^^^^^^^^^^^^^^^^^^^^
FileNotFoundError: [Errno 2] No such file or directory: 'long.osx'
